<?xml version="1.0" ?>
<!-- =================================================================================== -->
<!-- |    This document was autogenerated by xacro from onrobot_3fg15_gripper.xacro    | -->
<!-- |    EDITING THIS FILE BY HAND IS NOT RECOMMENDED                                 | -->
<!-- =================================================================================== -->
<robot name="onrobot_3fg15_gripper">

<joint name="gripper_base_joint" type="fixed">
<insert_block name="origin"/>
<parent link="${parent}"/>
<child link="gripper_base_link"/>
</joint>

<!-- BASE LINK -->
<link name="gripper_base_link">
<inertial>
<mass value="0.25" />
<origin xyz="0 0 0" />
<inertia  ixx="1.0" ixy="0.0"  ixz="0.0"  iyy="1.0"  iyz="0.0"  izz="1.0" />
</inertial>

<visual>
<origin xyz="0.0 0.0 0.0" rpy="0.0 0.0 0.0" />
<geometry>
<mesh filename="meshes/onrobot_3fg15_base.stl" scale="1 1 1"/>
</geometry>
<material name="grey">
<color rgba="0.5 0.5 0.5 1"/>
</material>
</visual>

<collision>
<origin xyz="0.0 0 0" rpy="0 0 0" />
<geometry>
<!--box size="0.146 0.05 0.0735"/-->
<mesh filename="meshes/onrobot_3fg15_base.stl" scale="1 1 1"/>
</geometry>
</collision>
</link>

<gazebo reference="gripper_base_link">
<material>Gazebo/Grey</material>
<turnGravityOff>false</turnGravityOff>
</gazebo>


<xacro:macro name="mimic_joint_plugin_gazebo" params="parent_joint mimic_joint has_pid:=false multiplier:=1.0 offset:=0 sensitiveness:=0.0 max_effort:=1.0 robot_namespace:=''">
<gazebo>
<plugin name="${mimic_joint}_mimic_joint_plugin" filename="libroboticsgroup_gazebo_mimic_joint_plugin.so">
<joint>${parent_joint}</joint>
<mimicJoint>${mimic_joint}</mimicJoint>
<xacro:if value="${has_pid}">                    
<hasPID />
</xacro:if>
<multiplier>${multiplier}</multiplier>
<offset>${offset}</offset>
<sensitiveness>${sensitiveness}</sensitiveness>   
<maxEffort>${max_effort}</maxEffort>              
<xacro:unless value="${robot_namespace == ''}">
<robotNamespace>($robot_namespace)</robotNamespace>
</xacro:unless>
</plugin>
</gazebo>
</xacro:macro>


<!-- FINGER UPPER -->

<joint name="gripper_upper_finger_joint" type="revolute">
<limit lower="0" upper="2.86775049" effort="1.0" velocity="0.6"/> 
<axis xyz="1 0 0"/>
<origin xyz="0.1022 0.0 -0.03" rpy="0.0 0.0 0.0" /> 
<parent link="gripper_base_link"/>
<child link="gripper_upper_finger" />
<dynamics damping="0" friction="0"/>
</joint>

<transmission name="gripper_base_trans_upper">
<type>transmission_interface/SimpleTransmission</type>
<actuator name="gripper_base_motor_upper">
<mechanicalReduction>1</mechanicalReduction>
<motorTorqueConstant>1</motorTorqueConstant>
</actuator>
<joint name="gripper_upper_finger_joint" >
<hardwareInterface>hardware_interface/PositionJointInterface</hardwareInterface>
</joint>
</transmission>

<link name="gripper_upper_finger">
<inertial>
<mass value="0.1" />
<origin xyz="0 0 0" />
<inertia ixx="1.0" ixy="0.0" ixz="0.0"
iyy="1.0" iyz="0.0" 
izz="1.0" />
</inertial>

<visual>
<origin xyz="0.0 0 0" rpy="0 0 0" />
<geometry>
<mesh filename="meshes/onrobot_3fg15_finger.stl" scale="1.0 1.0 1.0"/>
</geometry>
<material name="black">
<color rgba="0.2 0.2 0.2 1"/>
</material>
</visual>

<collision>
<origin xyz="0 0 0" rpy="0 0 0" />
<geometry>
<mesh filename="meshes/onrobot_3fg15_finger.stl" scale="1.0 1.0 1.0"/>
</geometry>
</collision>
<contact_coefficients kd="1.0" kp="1000.0" mu="0"/>
</link>

<gazebo reference="gripper_upper_finger">
<material>Gazebo/White</material>
<turnGravityOff>false</turnGravityOff>
</gazebo>


<!-- THUMB UPPER -->

<joint name="gripper_upper_thumb_joint" type="fixed">
<xacro:if value="${position == 1}">
<origin xyz="0.0095 0 0.0135" rpy="0.0 0.0 0" /> 
</xacro:if>
<xacro:if value="${position == 2}">
<origin xyz="0.0095 0 0.0045" rpy="0 0 0" /> 
</xacro:if>
<xacro:if value="${position == 3}">
<origin xyz="0.0095 0 -0.0045" rpy="0 0 0" /> 
</xacro:if> 
<parent link="gripper_upper_finger"/>
<child link="gripper_upper_thumb" />
</joint>


<link name="gripper_upper_thumb">
<inertial>
<mass value="0.1" />
<origin xyz="0 0 0" />
<inertia ixx="1.0" ixy="0.0" ixz="0.0"
iyy="1.0" iyz="0.0" 
izz="1.0" />
</inertial>

<visual>
<origin xyz="0.0 0 0" rpy="${-M_PI/2} 0 0" />
<geometry>
<mesh filename="meshes/onrobot_3fg15_thumb.stl" scale="1.0 1.0 1.0"/>
</geometry>
<material name="black">
<color rgba="0.2 0.2 0.2 1"/>
</material>
</visual>

<collision>
<origin xyz="0 0 0" rpy="${-M_PI/2} 0 0" />
<geometry>
<mesh filename="meshes/onrobot_3fg15_thumb.stl" scale="1.0 1.0 1.0"/>
</geometry>
</collision>
<contact_coefficients kd="1.0" kp="1000.0" mu="1000" mu2="1000"/>
</link>

<gazebo reference="gripper_upper_thumb">
<material>Gazebo/Blue</material>
<turnGravityOff>false</turnGravityOff>
</gazebo>


<!-- FINGER LEFT -->

<joint name="gripper_left_finger_joint" type="revolute">
<limit lower="0" upper="2.86775049" effort="1.0" velocity="0.6"/> 
<axis xyz="1 0 0"/>
<origin xyz="0.1022 0.02598 0.015" rpy="2.0944 0 0" /> 
<parent link="gripper_base_link"/>
<child link="gripper_left_finger" />
<dynamics damping="0" friction="0"/>
<mimic joint="gripper_upper_finger_joint" multiplier="1.0" offset="0"/> 
</joint>

<xacro:mimic_joint_plugin_gazebo parent_joint="gripper_upper_finger_joint" 
            mimic_joint="gripper_left_finger_joint" has_pid="false" multiplier="1.0" max_effort="10.0" />

<link name="gripper_left_finger">
<inertial>
<mass value="0.1" />
<origin xyz="0 0 0" />
<inertia ixx="1.0" ixy="0.0" ixz="0.0"
iyy="1.0" iyz="0.0" 
izz="1.0" />
</inertial>

<visual>
<origin xyz="0.0 0 0" rpy="0 0 0" />
<geometry>
<mesh filename="meshes/onrobot_3fg15_finger.stl" scale="1.0 1.0 1.0"/>
</geometry>
<material name="black">
<color rgba="0.2 0.2 0.2 1"/>
</material>
</visual>

<collision>
<origin xyz="0 0 0" rpy="0 0 0" />
<geometry>
<mesh filename="meshes/onrobot_3fg15_finger.stl" scale="1.0 1.0 1.0"/>
</geometry>
</collision>
<contact_coefficients kd="1.0" kp="1000.0" mu="0"/>
</link>

<gazebo reference="gripper_left_finger">
<material>Gazebo/White</material>
<turnGravityOff>false</turnGravityOff>
</gazebo>


<!-- THUMB LEFT -->

<joint name="gripper_left_thumb_joint" type="fixed">
<xacro:if value="${position == 1}">
<origin xyz="0.0095 0 0.0135" rpy="0.0 0.0 0" /> 
</xacro:if>
<xacro:if value="${position == 2}">
<origin xyz="0.0095 0 0.0045" rpy="0 0 0" /> 
</xacro:if>
<xacro:if value="${position == 3}">
<origin xyz="0.0095 0 -0.0045" rpy="0 0 0" /> 
</xacro:if> 
<parent link="gripper_left_finger"/>
<child link="gripper_left_thumb" />
</joint>

<link name="gripper_left_thumb">
<inertial>
<mass value="0.1" />
<origin xyz="0 0 0" />
<inertia ixx="1.0" ixy="0.0" ixz="0.0"
iyy="1.0" iyz="0.0" 
izz="1.0" />
</inertial>

<visual>
<origin xyz="0 0 0" rpy="${-M_PI/2} 0 0" />
<geometry>
<mesh filename="meshes/onrobot_3fg15_thumb.stl" scale="1.0 1.0 1.0"/>
</geometry>
<material name="black">
<color rgba="0.2 0.2 0.2 1"/>
</material>
</visual>

<collision>
<origin xyz="0 0 0" rpy="${-M_PI/2} 0 0" />
<geometry>
<mesh filename="meshes/onrobot_3fg15_thumb.stl" scale="1.0 1.0 1.0"/>
</geometry>
</collision>
<contact_coefficients kd="1.0" kp="1000.0" mu="1000" mu2="1000"/>
</link>

<gazebo reference="gripper_left_thumb">
<material>Gazebo/Blue</material>
<turnGravityOff>false</turnGravityOff>
</gazebo>


<!-- FINGER RIGHT -->

<joint name="gripper_right_finger_joint" type="revolute">
<limit lower="0" upper="2.86775049" effort="1.0" velocity="0.6"/> 
<axis xyz="1 0 0"/>
<origin xyz="0.1022 -0.02598 0.015" rpy="-2.0944 0 0" /> 
<parent link="gripper_base_link"/>
<child link="gripper_right_finger" />
<dynamics damping="0" friction="0"/>
<mimic joint="gripper_upper_finger_joint" multiplier="1.0" offset="0"/> 
</joint>

<xacro:mimic_joint_plugin_gazebo parent_joint="gripper_upper_finger_joint" 
            mimic_joint="gripper_right_finger_joint" has_pid="false" multiplier="1.0" max_effort="10.0" />

<link name="gripper_right_finger">
<inertial>
<mass value="0.1" />
<origin xyz="0 0 0" />
<inertia ixx="1.0" ixy="0.0" ixz="0.0"
iyy="1.0" iyz="0.0" 
izz="1.0" />
</inertial>

<visual>
<origin xyz="0.0 0 0" rpy="0 0 0" />
<geometry>
<mesh filename="meshes/onrobot_3fg15_finger.stl" scale="1.0 1.0 1.0"/>
</geometry>
<material name="black">
<color rgba="0.2 0.2 0.2 1"/>
</material>
</visual>

<collision>
<origin xyz="0 0 0" rpy="0 0 0" />
<geometry>
<mesh filename="meshes/onrobot_3fg15_finger.stl" scale="1.0 1.0 1.0"/>
</geometry>
</collision>
<contact_coefficients kd="1.0" kp="1000.0" mu="0"/>
</link>

<gazebo reference="gripper_right_finger">
<material>Gazebo/White</material>
<turnGravityOff>false</turnGravityOff>
</gazebo>


<!-- THUMB RIGHT -->

<joint name="gripper_right_thumb_joint" type="fixed">
<xacro:if value="${position == 1}">
<origin xyz="0.0095 0 0.0135" rpy="0.0 0.0 0" /> 
</xacro:if>
<xacro:if value="${position == 2}">
<origin xyz="0.0095 0 0.0045" rpy="0 0 0" /> 
</xacro:if>
<xacro:if value="${position == 3}">
<origin xyz="0.0095 0 -0.0045" rpy="0 0 0" /> 
</xacro:if> 
<parent link="gripper_right_finger"/>
<child link="gripper_right_thumb" />
</joint>

<link name="gripper_right_thumb">
<inertial>
<mass value="0.1" />
<origin xyz="0 0 0" />
<inertia ixx="1.0" ixy="0.0" ixz="0.0"
iyy="1.0" iyz="0.0" 
izz="1.0" />
</inertial>

<visual>
<origin xyz="0 0 0" rpy="${-M_PI/2} 0 0" />
<geometry>
<mesh filename="meshes/onrobot_3fg15_thumb.stl" scale="1.0 1.0 1.0"/>
</geometry>
<material name="black">
<color rgba="0.2 0.2 0.2 1"/>
</material>
</visual>

<collision>
<origin xyz="0 0 0" rpy="${-M_PI/2} 0 0" />
<geometry>
<mesh filename="meshes/onrobot_3fg15_thumb.stl" scale="1.0 1.0 1.0"/>
</geometry>
</collision>
<contact_coefficients kd="1.0" kp="1000.0" mu="1000" mu2="1000"/>
</link>

<gazebo reference="gripper_right_thumb">
<material>Gazebo/Blue</material>
<turnGravityOff>false</turnGravityOff>
</gazebo>
</robot>

